<?xml version='1.0'?>

<sdf version='1.6'>
    <model name="Mini_CIM">
        <link name="motor">
            <pose>0 0 -0.042671999999999995 0 0 0</pose>
            <collision name="motor_collision">
                <geometry>
                    <cylinder>
                        <radius>0.03175</radius>
                        <length>0.08534399999999999</length>
                    </cylinder>
                </geometry>
            </collision>
            <visual name="motor_visual">
                <geometry>
                    <cylinder>
                        <radius>0.03175</radius>
                        <length>0.08534399999999999</length>
                    </cylinder>
                </geometry>
            </visual>
        </link>
        <link name="motor_shaft">
            <pose>0 0 0.0178 0 0 0</pose>
            <collision name="motor_shaft_collision">
                <geometry>
                    <cylinder>
                        <radius>0.008</radius>
                        <length>0.0356</length>
                    </cylinder>
                </geometry>
            </collision>
            <visual name="motor_shaft_visual">
                <geometry>
                    <cylinder>
                        <radius>0.008</radius>
                        <length>0.0356</length>
                    </cylinder>
                </geometry>
            </visual>
        </link>
        <joint name="motor_shaft_to_motor" type="revolute">
            <pose>0 0 -0.0178 0 0 0</pose>
            <child>motor_shaft</child>
            <parent>motor</parent>
            <axis>
                <use_parent_model_frame>true</use_parent_model_frame>
                <xyz>0.0 0.0 1.0</xyz>
            </axis>
        </joint>
    </model>
</sdf>