<?xml version='1.0'?>
<%
    # Geometry in meters
    inches_to_meters = 0.0254
    motor_radius = (2.5/2.0) * inches_to_meters
    motor_length = 3.36 * inches_to_meters
    output_shaft_radius = 0.008
    output_shaft_length = 0.0356
%>
<sdf version='1.6'>
    <model name="Mini_CIM">
        <link name="motor">
            <pose>0 0 <%= -(motor_length/2.0)%> 0 0 0</pose>
            <collision name="motor_collision">
                <geometry>
                    <cylinder>
                        <radius><%= motor_radius%></radius>
                        <length><%= motor_length%></length>
                    </cylinder>
                </geometry>
            </collision>
            <visual name="motor_visual">
                <geometry>
                    <cylinder>
                        <radius><%= motor_radius%></radius>
                        <length><%= motor_length%></length>
                    </cylinder>
                </geometry>
            </visual>
        </link>
        <link name="motor_shaft">
            <pose>0 0 <%= output_shaft_length/2.0%> 0 0 0</pose>
            <collision name="motor_shaft_collision">
                <geometry>
                    <cylinder>
                        <radius><%= output_shaft_radius%></radius>
                        <length><%= output_shaft_length%></length>
                    </cylinder>
                </geometry>
            </collision>
            <visual name="motor_shaft_visual">
                <geometry>
                    <cylinder>
                        <radius><%= output_shaft_radius%></radius>
                        <length><%= output_shaft_length%></length>
                    </cylinder>
                </geometry>
            </visual>
        </link>
        <joint name="motor_shaft_to_motor" type="revolute">
            <pose>0 0 <%= -(output_shaft_length/2.0)%> 0 0 0</pose>
            <child>motor_shaft</child>
            <parent>motor</parent>
            <axis>
                <xyz>0.0 0.0 1.0</xyz>
            </axis>
        </joint>
    </model>
</sdf>